<?xml version="1.0" ?>

<robot name="spotmicroai">
  <!-- Params -->
  <!-- Macros -->
  <!-- Robot Body -->
  <!--test-->
  <link name="base_link">
    <visual>
      <geometry>
        <mesh filename="file://$(find quadruped_robot)/stl/mainbody.stl" scale="0.001 0.001 0.001"/>
      </geometry>
      <origin rpy="0 0 0" xyz="-0.045 -0.060 -0.015"/>
      <material name="black">
        <color rgba="0.0 0.0 0.0 1.0"/>
      </material>
    </visual>
    <collision>
      <geometry>
        <mesh filename="file://$(find quadruped_robot)/stl/mainbody.stl" scale="0.001 0.001 0.001"/>
      </geometry>
      <origin rpy="0 0 0" xyz="-0.045 -0.060 -0.015"/>
    </collision>
    <inertial>
        <mass value="2.0"/> <!-- Approximate base mass in kg -->
        <origin xyz="0.0 0.0 0.0" rpy="0 0 0"/> <!-- Adjust center of mass -->
        <inertia 
            ixx="0.007" 
            ixy="0.0" 
            ixz="0.0" 
            iyy="0.008" 
            iyz="0.0" 
            izz="0.009"/>
    </inertial>
  </link>

  <!-- Lidar Backpack -->
  <link name="lidar_link">
    <visual>
      <geometry>
        <mesh filename="file://$(find quadruped_robot)/stl/rplidar_main.STL" scale="0.001 0.001 0.001"/>
      </geometry>
      <material name="black"/>
      <origin rpy="1.57075 0 0" xyz="-0.06425 0.02885 0"/>
    </visual>
    <collision>
      <geometry>
        <mesh filename="file://$(find quadruped_robot)/stl/rplidar_main.STL" scale="0.001 0.001 0.001"/>
      </geometry>
      <origin rpy="1.57075 0 0" xyz="-0.06425 0.02885 0"/>
    </collision>
    <inertial>
      <mass value="0.02"/>
      <inertia ixx="0.05" ixy="0" ixz="0" iyy="0.05" iyz="0" izz="0.05"/>
    </inertial>
  </link>
  <joint name="base_lidar" type="fixed">
    <parent link="base_link"/>
    <child link="lidar_link"/>
    <origin xyz="0 0 0.035"/>
  </joint>

  <link name="rear_link">
    <visual>
      <geometry>
        <mesh filename="file://$(find quadruped_robot)/stl/backpart.stl" scale="0.001 0.001 0.001"/>
      </geometry>
      <origin rpy="0 0 0" xyz="-0.040 -0.060 -0.0140"/>
      <material name="yellow">
        <color rgba="0.92 0.83 0.0 1"/>
      </material>
    </visual>
    <collision>
      <geometry>
        <mesh filename="file://$(find quadruped_robot)/stl/backpart.stl" scale="0.001 0.001 0.001"/>
      </geometry>
      <origin rpy="0 0 0" xyz="-0.040 -0.060 -0.0140"/>
    </collision>
    <inertial>
      <mass value="0.20"/>
      <inertia ixx="0.05" ixy="0" ixz="0" iyy="0.05" iyz="0" izz="0.05"/>
    </inertial>
  </link>
  <joint name="base_rear" type="fixed">
    <parent link="base_link"/>
    <child link="rear_link"/>
  </joint>

  <link name="front_link">
    <visual>
      <geometry>
        <mesh filename="file://$(find quadruped_robot)/stl/frontpart.stl" scale="0.001 0.001 0.001"/>
      </geometry>
      <origin rpy="0 0 0" xyz="-0.040 -0.060 -0.0140"/>
      <material name="yellow">
        <color rgba="0.92 0.83 0.0 1"/>
      </material>
    </visual>
    <collision>
      <geometry>
        <mesh filename="file://$(find quadruped_robot)/stl/frontpart.stl" scale="0.001 0.001 0.001"/>
      </geometry>
      <origin rpy="0 0 0" xyz="-0.040 -0.060 -0.0140"/>
    </collision>
    <inertial>
      <mass value="0.20"/>
      <inertia ixx="0.05" ixy="0" ixz="0" iyy="0.05" iyz="0" izz="0.05"/>
    </inertial>
  </link>
  <joint name="base_front" type="fixed">
    <parent link="base_link"/>
    <child link="front_link"/>
  </joint>

  <link name="imu_link">
    <inertial>
      <mass value="0.01"/>
      <origin rpy="0 0 0" xyz="0 0 0"/>
      <inertia ixx="0.0001" ixy="0" ixz="0" iyy="0.0001" iyz="0" izz="0.0001"/>
    </inertial>
  </link>
  <joint name="imu_joint" type="fixed">
    <parent link="base_link"/>
    <child link="imu_link"/>
    <origin rpy="0 0 0" xyz="0 0 0"/>
  </joint>

  <!-- create Legs -->
  <link name="front_left_shoulder_link">
    <visual>
      <geometry>
        <mesh filename="file://$(find quadruped_robot)/stl/lshoulder.stl" scale="0.001 0.001 0.001"/>
      </geometry>
      <origin rpy="0 0 0" xyz="-0.135 -0.02 -0.01"/>
      <material name="black">
        <color rgba="0.0 0.0 0.0 1.0"/>
      </material>
    </visual>
    <collision>
      <geometry>
        <mesh filename="file://$(find quadruped_robot)/stl/lshoulder.stl" scale="0.001 0.001 0.001"/>
      </geometry>
      <origin rpy="0 0 0" xyz="-0.135 -0.02 -0.01"/>
    </collision>
    <inertial>
      <mass value="0.30"/>
      <inertia ixx="0.0005" ixy="0" ixz="0" iyy="0.0006" iyz="0" izz="0.0007"/>
    </inertial>
  </link>
  <link name="front_left_leg_link_cover">
    <visual>
      <geometry>
        <mesh filename="file://$(find quadruped_robot)/stl/larm_cover.stl" scale="0.001 0.001 0.001"/>
      </geometry>
      <origin rpy="0 0 0" xyz="-0.125 0.04 -0.02"/>
      <material name="yellow">
        <color rgba="0.92 0.83 0.0 1"/>
      </material>
    </visual>
  </link>
  <link name="front_left_leg_link">
    <visual>
      <geometry>
        <mesh filename="file://$(find quadruped_robot)/stl/larm.stl" scale="0.001 0.001 0.001"/>
      </geometry>
      <origin rpy="0 0 0" xyz="-0.125 0.04 -0.02"/>
      <material name="black">
        <color rgba="0.0 0.0 0.0 1.0"/>
      </material>
    </visual>
    <collision>
      <geometry>
        <mesh filename="file://$(find quadruped_robot)/stl/larm.stl" scale="0.001 0.001 0.001"/>
      </geometry>
      <origin rpy="0 0 0" xyz="-0.125 0.04 -0.02"/>
    </collision>
    <inertial>
      <mass value="0.2"/>
      <inertia ixx="0.0002" ixy="0" ixz="0" iyy="0.0003" iyz="0" izz="0.0004"/>
    </inertial>
  </link>
  <link name="front_left_foot_link">
    <visual>
      <geometry>
        <mesh filename="file://$(find quadruped_robot)/stl/lfoot.stl" scale="0.001 0.001 0.001"/>
      </geometry>
      <origin rpy="0 0 0" xyz="-0.120 0.04 0.1"/>
      <material name="black">
        <color rgba="0.0 0.0 0.0 1.0"/>
      </material>
    </visual>
    <collision>
      <geometry>
        <mesh filename="file://$(find quadruped_robot)/stl/lfoot.stl" scale="0.001 0.001 0.001"/>
      </geometry>
      <origin rpy="0 0 0" xyz="-0.120 0.04 0.1"/>
    </collision>
    <inertial>
      <mass value="0.1"/>
      <inertia ixx="0.0001" ixy="0" ixz="0" iyy="0.0001" iyz="0" izz="0.0001"/>
    </inertial>
  </link>
  <link name="front_left_toe_link">
    <visual>
      <geometry>
        <mesh filename="file://$(find quadruped_robot)/stl/foot.stl" scale="0.001 0.001 0.001"/>
      </geometry>
      <origin rpy="0 -0.40010 0" xyz="0 -0.01 0"/>
      <material name="grey">
        <color rgba="0.6 0.6 0.6 1"/>
      </material>
    </visual>
    <collision>
      <geometry>
        <mesh filename="file://$(find quadruped_robot)/stl/foot.stl" scale="0.001 0.001 0.001"/>
      </geometry>
      <origin rpy="0 -0.40010 0" xyz="0 -0.01 0"/>
      <contact_coefficients mu="1.5"/>
    </collision>
    <inertial>
      <mass value="0.05"/>
      <inertia ixx="0.00005" ixy="0" ixz="0" iyy="0.00005" iyz="0" izz="0.00005"/>
    </inertial>
  </link>

  <joint name="front_left_shoulder" type="revolute">
    <parent link="base_link"/>
    <child link="front_left_shoulder_link"/>
    <axis xyz="1 0 0"/>
    <origin rpy="0 0 0" xyz="-0.093 -0.036 0"/>
    <limit effort="25" lower="-3.141592653589793" upper="3.141592653589793" velocity="1.5"/>
    <dynamics damping="0.0" friction="0.5"/>
  </joint>
  <joint name="front_left_leg" type="revolute">
    <parent link="front_left_shoulder_link"/>
    <child link="front_left_leg_link"/>
    <axis xyz="0 1 0"/>
    <origin rpy="0 0 0" xyz="0 -0.052 0"/>
    <limit effort="25" lower="-3.141592653589793" upper="3.141592653589793" velocity="1.5"/>
    <dynamics damping="0.0" friction="0.0"/>
  </joint>
  <joint name="front_left_leg_cover_joint" type="fixed">
    <parent link="front_left_leg_link"/>
    <child link="front_left_leg_link_cover"/>
    <origin xyz="0 0 0"/>
  </joint>
  <joint name="front_left_foot" type="revolute">
    <parent link="front_left_leg_link"/>
    <child link="front_left_foot_link"/>
    <axis xyz="0 1 0"/>
    <origin rpy="0 0 0" xyz="-0.01 0 -0.12"/>
        <limit effort="25" lower="-3.141592653589793" upper="3.141592653589793" velocity="1.5"/>
    <dynamics damping="0.0" friction="0.5"/>
  </joint>
  <joint name="front_left_toe" type="fixed">
    <parent link="front_left_foot_link"/>
    <child link="front_left_toe_link"/>
    <origin xyz="0 0 -0.115"/>
  </joint>

  <link name="front_right_shoulder_link">
    <visual>
      <geometry>
        <mesh filename="file://$(find quadruped_robot)/stl/rshoulder.stl" scale="0.001 0.001 0.001"/>
      </geometry>
      <origin rpy="0 0 0" xyz="-0.135 -0.09 -0.01"/>
      <material name="black">
        <color rgba="0.0 0.0 0.0 1.0"/>
      </material>
    </visual>
    <collision>
      <geometry>
        <mesh filename="file://$(find quadruped_robot)/stl/rshoulder.stl" scale="0.001 0.001 0.001"/>
      </geometry>
      <origin rpy="0 0 0" xyz="-0.135 -0.09 -0.01"/>
    </collision>
    <inertial>
      <mass value="0.30"/>
      <inertia ixx="0.0005" ixy="0" ixz="0" iyy="0.0006" iyz="0" izz="0.0007"/>
    </inertial>
  </link>
  <link name="front_right_leg_link_cover">
    <visual>
      <geometry>
        <mesh filename="file://$(find quadruped_robot)/stl/rarm_cover.stl" scale="0.001 0.001 0.001"/>
      </geometry>
      <origin rpy="0 0 0" xyz="-0.125 -0.15 -0.02"/>
      <material name="yellow">
        <color rgba="0.92 0.83 0.0 1"/>
      </material>
    </visual>
  </link>
  <link name="front_right_leg_link">
    <visual>
      <geometry>
        <mesh filename="file://$(find quadruped_robot)/stl/rarm.stl" scale="0.001 0.001 0.001"/>
      </geometry>
      <origin rpy="0 0 0" xyz="-0.125 -0.15 -0.02"/>
      <material name="black">
        <color rgba="0.0 0.0 0.0 1.0"/>
      </material>
    </visual>
    <collision>
      <geometry>
        <mesh filename="file://$(find quadruped_robot)/stl/rarm.stl" scale="0.001 0.001 0.001"/>
      </geometry>
      <origin rpy="0 0 0" xyz="-0.125 -0.15 -0.02"/>
    </collision>
    <inertial>
      <mass value="0.2"/>
      <inertia ixx="0.0002" ixy="0" ixz="0" iyy="0.0003" iyz="0" izz="0.0004"/>
    </inertial>
  </link>
  <link name="front_right_foot_link">
    <visual>
      <geometry>
        <mesh filename="file://$(find quadruped_robot)/stl/rfoot.stl" scale="0.001 0.001 0.001"/>
      </geometry>
      <origin rpy="0 0 0" xyz="-0.120 -0.15 0.1"/>
      <material name="black">
        <color rgba="0.0 0.0 0.0 1.0"/>
      </material>
    </visual>
    <collision>
      <geometry>
        <mesh filename="file://$(find quadruped_robot)/stl/rfoot.stl" scale="0.001 0.001 0.001"/>
      </geometry>
      <origin rpy="0 0 0" xyz="-0.120 -0.15 0.1"/>
    </collision>
    <inertial>
      <mass value="0.1"/>
      <inertia ixx="0.0001" ixy="0" ixz="0" iyy="0.0001" iyz="0" izz="0.0001"/>
    </inertial>
  </link>
  <link name="front_right_toe_link">
    <visual>
      <geometry>
        <mesh filename="file://$(find quadruped_robot)/stl/foot.stl" scale="0.001 0.001 0.001"/>
      </geometry>
      <origin rpy="0 -0.40010 0" xyz="0 -0.01 0"/>
      <material name="grey">
        <color rgba="0.6 0.6 0.6 1"/>
      </material>
    </visual>
    <collision>
      <geometry>
        <mesh filename="file://$(find quadruped_robot)/stl/foot.stl" scale="0.001 0.001 0.001"/>
      </geometry>
      <origin rpy="0 -0.40010 0" xyz="0 -0.01 0"/>
      <contact_coefficients mu="1.5"/>
    </collision>
    <inertial>
      <mass value="0.05"/>
      <inertia ixx="0.00005" ixy="0" ixz="0" iyy="0.00005" iyz="0" izz="0.00005"/>
    </inertial>
  </link>
  
  <joint name="front_right_shoulder" type="revolute">
    <parent link="base_link"/>
    <child link="front_right_shoulder_link"/>
    <axis xyz="1 0 0"/>
    <origin rpy="0 0 0" xyz="-0.093 0.036 0"/>
    <limit effort="25" lower="-3.141592653589793" upper="3.141592653589793" velocity="1.5"/>
    <dynamics damping="0.0" friction="0.5"/>
  </joint>
  <joint name="front_right_leg" type="revolute">
    <parent link="front_right_shoulder_link"/>
    <child link="front_right_leg_link"/>
    <axis xyz="0 1 0"/>
    <origin rpy="0 0 0" xyz="0 0.052 0"/>
    <limit effort="25" lower="-3.141592653589793" upper="3.141592653589793" velocity="1.5"/>
    <dynamics damping="0.0" friction="0.0"/>
  </joint>
  <joint name="front_right_leg_cover_joint" type="fixed">
    <parent link="front_right_leg_link"/>
    <child link="front_right_leg_link_cover"/>
    <origin xyz="0 0 0"/>
  </joint>
  <joint name="front_right_foot" type="revolute">
    <parent link="front_right_leg_link"/>
    <child link="front_right_foot_link"/>
    <axis xyz="0 1 0"/>
    <origin rpy="0 0 0" xyz="-0.01 0 -0.12"/>
        <limit effort="25" lower="-3.141592653589793" upper="3.141592653589793" velocity="1.5"/>
    <dynamics damping="0.0" friction="0.5"/>
  </joint>
  <joint name="front_right_toe" type="fixed">
    <parent link="front_right_foot_link"/>
    <child link="front_right_toe_link"/>
    <origin xyz="0 0 -0.115"/>
  </joint>

  <link name="rear_left_shoulder_link">
    <visual>
      <geometry>
        <mesh filename="file://$(find quadruped_robot)/stl/lshoulder.stl" scale="0.001 0.001 0.001"/>
      </geometry>
      <origin rpy="0 0 0" xyz="-0.135 -0.02 -0.01"/>
      <material name="black">
        <color rgba="0.0 0.0 0.0 1.0"/>
      </material>
    </visual>
    <collision>
      <geometry>
        <mesh filename="file://$(find quadruped_robot)/stl/lshoulder.stl" scale="0.001 0.001 0.001"/>
      </geometry>
      <origin rpy="0 0 0" xyz="-0.135 -0.02 -0.01"/>
    </collision>
    <inertial>
      <mass value="0.30"/>
      <inertia ixx="0.0005" ixy="0" ixz="0" iyy="0.0006" iyz="0" izz="0.0007"/>
    </inertial>
  </link>
  <link name="rear_left_leg_link_cover">
    <visual>
      <geometry>
        <mesh filename="file://$(find quadruped_robot)/stl/larm_cover.stl" scale="0.001 0.001 0.001"/>
      </geometry>
      <origin rpy="0 0 0" xyz="-0.125 0.04 -0.02"/>
      <material name="yellow">
        <color rgba="0.92 0.83 0.0 1"/>
      </material>
    </visual>
  </link>
  <link name="rear_left_leg_link">
    <visual>
      <geometry>
        <mesh filename="file://$(find quadruped_robot)/stl/larm.stl" scale="0.001 0.001 0.001"/>
      </geometry>
      <origin rpy="0 0 0" xyz="-0.125 0.04 -0.02"/>
      <material name="black">
        <color rgba="0.0 0.0 0.0 1.0"/>
      </material>
    </visual>
    <collision>
      <geometry>
        <mesh filename="file://$(find quadruped_robot)/stl/larm.stl" scale="0.001 0.001 0.001"/>
      </geometry>
      <origin rpy="0 0 0" xyz="-0.125 0.04 -0.02"/>
    </collision>
    <inertial>
      <mass value="0.2"/>
      <inertia ixx="0.0002" ixy="0" ixz="0" iyy="0.0003" iyz="0" izz="0.0004"/>
    </inertial>
  </link>
  <link name="rear_left_foot_link">
    <visual>
      <geometry>
        <mesh filename="file://$(find quadruped_robot)/stl/lfoot.stl" scale="0.001 0.001 0.001"/>
      </geometry>
      <origin rpy="0 0 0" xyz="-0.120 0.04 0.1"/>
      <material name="black">
        <color rgba="0.0 0.0 0.0 1.0"/>
      </material>
    </visual>
    <collision>
      <geometry>
        <mesh filename="file://$(find quadruped_robot)/stl/lfoot.stl" scale="0.001 0.001 0.001"/>
      </geometry>
      <origin rpy="0 0 0" xyz="-0.120 0.04 0.1"/>
    </collision>
    <inertial>
      <mass value="0.1"/>
      <inertia ixx="0.0001" ixy="0" ixz="0" iyy="0.0001" iyz="0" izz="0.0001"/>
    </inertial>
  </link>
  <link name="rear_left_toe_link">
    <visual>
      <geometry>
        <mesh filename="file://$(find quadruped_robot)/stl/foot.stl" scale="0.001 0.001 0.001"/>
      </geometry>
      <origin rpy="0 -0.40010 0" xyz="0 -0.01 0"/>
      <material name="grey">
        <color rgba="0.6 0.6 0.6 1"/>
      </material>
    </visual>
    <collision>
      <geometry>
        <mesh filename="file://$(find quadruped_robot)/stl/foot.stl" scale="0.001 0.001 0.001"/>
      </geometry>
      <origin rpy="0 -0.40010 0" xyz="0 -0.01 0"/>
      <contact_coefficients mu="1.5"/>
    </collision>
    <inertial>
      <mass value="0.05"/>
      <inertia ixx="0.00005" ixy="0" ixz="0" iyy="0.00005" iyz="0" izz="0.00005"/>
    </inertial>
  </link>

  <joint name="rear_left_shoulder" type="revolute">
    <parent link="base_link"/>
    <child link="rear_left_shoulder_link"/>
    <axis xyz="1 0 0"/>
    <origin rpy="0 0 0" xyz="0.093 -0.036 0"/>
    <limit effort="25" lower="-3.141592653589793" upper="3.141592653589793" velocity="1.5"/>
    <dynamics damping="0.0" friction="0.5"/>
  </joint>
  <joint name="rear_left_leg" type="revolute">
    <parent link="rear_left_shoulder_link"/>
    <child link="rear_left_leg_link"/>
    <axis xyz="0 1 0"/>
    <origin rpy="0 0 0" xyz="0 -0.052 0"/>
    <limit effort="25" lower="-3.141592653589793" upper="3.141592653589793" velocity="1.5"/>
    <dynamics damping="0.0" friction="0.0"/>
  </joint>
  <joint name="rear_left_leg_cover_joint" type="fixed">
    <parent link="rear_left_leg_link"/>
    <child link="rear_left_leg_link_cover"/>
    <origin xyz="0 0 0"/>
  </joint>
  <joint name="rear_left_foot" type="revolute">
    <parent link="rear_left_leg_link"/>
    <child link="rear_left_foot_link"/>
    <axis xyz="0 1 0"/>
    <origin rpy="0 0 0" xyz="-0.01 0 -0.12"/>
        <limit effort="25" lower="-3.141592653589793" upper="3.141592653589793" velocity="1.5"/>
    <dynamics damping="0.0" friction="0.5"/>
  </joint>
  <joint name="rear_left_toe" type="fixed">
    <parent link="rear_left_foot_link"/>
    <child link="rear_left_toe_link"/>
    <origin xyz="0 0 -0.115"/>
  </joint>

  <link name="rear_right_shoulder_link">
    <visual>
      <geometry>
        <mesh filename="file://$(find quadruped_robot)/stl/rshoulder.stl" scale="0.001 0.001 0.001"/>
      </geometry>
      <origin rpy="0 0 0" xyz="-0.135 -0.09 -0.01"/>
      <material name="black">
        <color rgba="0.0 0.0 0.0 1.0"/>
      </material>
    </visual>
    <collision>
      <geometry>
        <mesh filename="file://$(find quadruped_robot)/stl/rshoulder.stl" scale="0.001 0.001 0.001"/>
      </geometry>
      <origin rpy="0 0 0" xyz="-0.135 -0.09 -0.01"/>
    </collision>
    <inertial>
      <mass value="0.30"/>
      <inertia ixx="0.0005" ixy="0" ixz="0" iyy="0.0006" iyz="0" izz="0.0007"/>
    </inertial>
  </link>
  <link name="rear_right_leg_link_cover">
    <visual>
      <geometry>
        <mesh filename="file://$(find quadruped_robot)/stl/rarm_cover.stl" scale="0.001 0.001 0.001"/>
      </geometry>
      <origin rpy="0 0 0" xyz="-0.125 -0.15 -0.02"/>
      <material name="yellow">
        <color rgba="0.92 0.83 0.0 1"/>
      </material>
    </visual>
  </link>
  <link name="rear_right_leg_link">
    <visual>
      <geometry>
        <mesh filename="file://$(find quadruped_robot)/stl/rarm.stl" scale="0.001 0.001 0.001"/>
      </geometry>
      <origin rpy="0 0 0" xyz="-0.125 -0.15 -0.02"/>
      <material name="black">
        <color rgba="0.0 0.0 0.0 1.0"/>
      </material>
    </visual>
    <collision>
      <geometry>
        <mesh filename="file://$(find quadruped_robot)/stl/rarm.stl" scale="0.001 0.001 0.001"/>
      </geometry>
      <origin rpy="0 0 0" xyz="-0.125 -0.15 -0.02"/>
    </collision>
    <inertial>
      <mass value="0.2"/>
      <inertia ixx="0.0002" ixy="0" ixz="0" iyy="0.0003" iyz="0" izz="0.0004"/>
    </inertial>
  </link>
  <link name="rear_right_foot_link">
    <visual>
      <geometry>
        <mesh filename="file://$(find quadruped_robot)/stl/rfoot.stl" scale="0.001 0.001 0.001"/>
      </geometry>
      <origin rpy="0 0 0" xyz="-0.120 -0.15 0.1"/>
      <material name="black">
        <color rgba="0.0 0.0 0.0 1.0"/>
      </material>
    </visual>
    <collision>
      <geometry>
        <mesh filename="file://$(find quadruped_robot)/stl/rfoot.stl" scale="0.001 0.001 0.001"/>
      </geometry>
      <origin rpy="0 0 0" xyz="-0.120 -0.15 0.1"/>
    </collision>
    <inertial>
      <mass value="0.1"/>
      <inertia ixx="0.0001" ixy="0" ixz="0" iyy="0.0001" iyz="0" izz="0.0001"/>
    </inertial>
  </link>
  <link name="rear_right_toe_link">
    <visual>
      <geometry>
        <mesh filename="file://$(find quadruped_robot)/stl/foot.stl" scale="0.001 0.001 0.001"/>
      </geometry>
      <origin rpy="0 -0.40010 0" xyz="0 -0.01 0"/>
      <material name="grey">
        <color rgba="0.6 0.6 0.6 1"/>
      </material>
    </visual>
    <collision>
      <geometry>
        <mesh filename="file://$(find quadruped_robot)/stl/foot.stl" scale="0.001 0.001 0.001"/>
      </geometry>
      <origin rpy="0 -0.40010 0" xyz="0 -0.01 0"/>
      <contact_coefficients mu="1.5"/>
    </collision>
    <inertial>
      <mass value="0.05"/>
      <inertia ixx="0.00005" ixy="0" ixz="0" iyy="0.00005" iyz="0" izz="0.00005"/>
    </inertial>
  </link>

  <joint name="rear_right_shoulder" type="revolute">
    <parent link="base_link"/>
    <child link="rear_right_shoulder_link"/>
    <axis xyz="1 0 0"/>
    <origin rpy="0 0 0" xyz="0.093 0.036 0"/>
    <limit effort="25" lower="-3.141592653589793" upper="3.141592653589793" velocity="1.5"/>
    <dynamics damping="0.0" friction="0.5"/>
  </joint>
  <joint name="rear_right_leg" type="revolute">
    <parent link="rear_right_shoulder_link"/>
    <child link="rear_right_leg_link"/>
    <axis xyz="0 1 0"/>
    <origin rpy="0 0 0" xyz="0 0.052 0"/>
    <limit effort="25" lower="-3.141592653589793" upper="3.141592653589793" velocity="1.5"/>
    <dynamics damping="0.0" friction="0.0"/>
  </joint>
  <joint name="rear_right_leg_cover_joint" type="fixed">
    <parent link="rear_right_leg_link"/>
    <child link="rear_right_leg_link_cover"/>
    <origin xyz="0 0 0"/>
  </joint>
  <joint name="rear_right_foot" type="revolute">
    <parent link="rear_right_leg_link"/>
    <child link="rear_right_foot_link"/>
    <axis xyz="0 1 0"/>
    <origin rpy="0 0 0" xyz="-0.01 0 -0.12"/>
        <limit effort="25" lower="-3.141592653589793" upper="3.141592653589793" velocity="1.5"/>
    <dynamics damping="0.0" friction="0.5"/>
  </joint>
  <joint name="rear_right_toe" type="fixed">
    <parent link="rear_right_foot_link"/>
    <child link="rear_right_toe_link"/>
    <origin xyz="0 0 -0.115"/>
  </joint>
 
  <!-- Gazebo-->
  <gazebo reference="base_link">
    <material>Gazebo/FlatBlack</material>
  </gazebo>
  <gazebo reference="rear_link">
    <material>Gazebo/Yellow</material>
  </gazebo>

  <gazebo reference="front_link">
    <material>Gazebo/Yellow</material>
  </gazebo>

  <gazebo reference="lidar_link">
    <sensor name="hokuyo" type="ray">
      <always_on>true</always_on>
      <update_rate>30</update_rate>
      <pose>0 0 0 0 0 0</pose>
      <visualize>false</visualize>
      <ray>
        <scan>
          <horizontal>
            <samples>1040</samples>
            <resolution>1</resolution>
            <min_angle>2.2689280275926285</min_angle>
            <max_angle>-2.2689280275926285</max_angle>
          </horizontal>
        </scan>
        <range>
          <min>0.2</min>
          <max>30.0</max>
          <resolution>0.01</resolution>
        </range>
        <noise>
          <type>gaussian</type>
          <mean>0.0</mean>
          <stddev>0.004</stddev>
        </noise>
      </ray>
      <plugin filename="libgazebo_ros_ray_sensor.so" name="gazebo_ros_hokuyo_controller">
        <ros>
          <namespace>lidar_link</namespace>
          <argument>~/out:=scan</argument>
        </ros>
        <!-- Set output to sensor_msgs/PointCloud to get same output type as gazebo_ros_block_laser -->
        <output_type>sensor_msgs/LaserScan</output_type>
        <!-- <frame_name> ommited, will default to block_laser_link -->
        <!-- min_intensity instead of hokuyoMinIntensity -->
        <min_intensity>100.0</min_intensity>
      </plugin>
    </sensor>
  </gazebo>

  <gazebo reference="lidar_link">
    <material>Gazebo/Black</material>
  </gazebo>
  
  <gazebo reference="imu_link">
    <sensor name="imu_controller" type="imu">
      <always_on>true</always_on>
      <update_rate>50</update_rate>
      <plugin filename="libgazebo_ros_imu_sensor.so" name="gazebo_ros_imu_sensor">
        <ros>
          <namespace>/imu</namespace>
          <argument>~/out:=data</argument>
        </ros>
        <!-- <updateRate>50.0</updateRate>
                        <bodyName>imu_link</bodyName>
                        <topicName>imu/data</topicName>
                        <accelDrift>0.005 0.005 0.005</accelDrift>
                        <accelGaussianNoise>0.005 0.005 0.005</accelGaussianNoise>
                        <rateDrift>0.005 0.005 0.005 </rateDrift>
                        <rateGaussianNoise>0.005 0.005 0.005 </rateGaussianNoise>
                        <headingDrift>0.005</headingDrift>
                        <headingGaussianNoise>0.005</headingGaussianNoise> -->
      </plugin>
    </sensor>
  </gazebo>
  
  <gazebo reference="front_left_shoulder_link">
    <material>Gazebo/Black</material>
  </gazebo>
  <gazebo reference="front_left_leg_link_cover">
    <material>Gazebo/Yellow</material>
  </gazebo>
  <gazebo reference="front_left_leg_link">
    <material>Gazebo/Black</material>
  </gazebo>
  <gazebo reference="front_left_foot_link">
    <kp>10000000000.0</kp>
    <kd>100.0</kd>
    <mu1>0.8</mu1>
    <mu2>0.8</mu2>
    <minDepth>0.05</minDepth>
    <material>Gazebo/Black</material>
  </gazebo>
  <gazebo reference="front_left_toe_link">
    <material>Gazebo/Grey</material>
  </gazebo>

  <gazebo reference="front_right_shoulder_link">
    <material>Gazebo/Black</material>
  </gazebo>
  <gazebo reference="front_right_leg_link_cover">
    <material>Gazebo/Yellow</material>
  </gazebo>
  <gazebo reference="front_right_leg_link">
    <material>Gazebo/Black</material>
  </gazebo>
  <gazebo reference="front_right_foot_link">
    <kp>10000000000.0</kp>
    <kd>100.0</kd>
    <mu1>0.8</mu1>
    <mu2>0.8</mu2>
    <minDepth>0.05</minDepth>
    <material>Gazebo/Black</material>
  </gazebo>
  <gazebo reference="front_right_toe_link">
    <material>Gazebo/Grey</material>
  </gazebo>


  <gazebo reference="rear_left_shoulder_link">
    <material>Gazebo/Black</material>
  </gazebo>
  <gazebo reference="rear_left_leg_link_cover">
    <material>Gazebo/Yellow</material>
  </gazebo>
  <gazebo reference="rear_left_leg_link">
    <material>Gazebo/Black</material>
  </gazebo>
  <gazebo reference="rear_left_foot_link">
    <kp>10000000000.0</kp>
    <kd>100.0</kd>
    <mu1>0.8</mu1>
    <mu2>0.8</mu2>
    <minDepth>0.05</minDepth>
    <material>Gazebo/Black</material>
  </gazebo>
  <gazebo reference="rear_left_toe_link">
    <material>Gazebo/Grey</material>
  </gazebo>

  <gazebo reference="rear_right_shoulder_link">
    <material>Gazebo/Black</material>
  </gazebo>
  <gazebo reference="rear_right_leg_link_cover">
    <material>Gazebo/Yellow</material>
  </gazebo>
  <gazebo reference="rear_right_leg_link">
    <material>Gazebo/Black</material>
  </gazebo>
  <gazebo reference="rear_right_foot_link">
    <kp>10000000000.0</kp>
    <kd>100.0</kd>
    <mu1>0.8</mu1>
    <mu2>0.8</mu2>
    <minDepth>0.05</minDepth>
    <material>Gazebo/Black</material>
  </gazebo>
  <gazebo reference="rear_right_toe_link">
    <material>Gazebo/Grey</material>
  </gazebo>

  <ros2_control name="front_left_shoulder_control" type="system">
    <hardware>
      <plugin>gazebo_ros2_control/GazeboSystem</plugin>
    </hardware>
    <joint name="front_left_shoulder">
      <command_interface name="effort"/>
      <state_interface name="position"/>
      <state_interface name="velocity"/>
    </joint>
  </ros2_control>
  <ros2_control name="front_left_leg_control" type="system">
    <hardware>
      <plugin>gazebo_ros2_control/GazeboSystem</plugin>
    </hardware>
    <joint name="front_left_leg">
      <command_interface name="effort"/>
      <state_interface name="position"/>
      <state_interface name="velocity"/>
    </joint>
  </ros2_control>
  <ros2_control name="front_left_foot_control" type="system">
    <hardware>
      <plugin>gazebo_ros2_control/GazeboSystem</plugin>
    </hardware>
    <joint name="front_left_foot">
      <command_interface name="effort"/>
      <state_interface name="position"/>
      <state_interface name="velocity"/>
    </joint>
  </ros2_control>

  <ros2_control name="front_right_shoulder_control" type="system">
    <hardware>
      <plugin>gazebo_ros2_control/GazeboSystem</plugin>
    </hardware>
    <joint name="front_right_shoulder">
      <command_interface name="effort"/>
      <state_interface name="position"/>
      <state_interface name="velocity"/>
    </joint>
  </ros2_control>
  <ros2_control name="front_right_leg_control" type="system">
    <hardware>
      <plugin>gazebo_ros2_control/GazeboSystem</plugin>
    </hardware>
    <joint name="front_right_leg">
      <command_interface name="effort"/>
      <state_interface name="position"/>
      <state_interface name="velocity"/>
    </joint>
  </ros2_control>
  <ros2_control name="front_right_foot_control" type="system">
    <hardware>
      <plugin>gazebo_ros2_control/GazeboSystem</plugin>
    </hardware>
    <joint name="front_right_foot">
      <command_interface name="effort"/>
      <state_interface name="position"/>
      <state_interface name="velocity"/>
    </joint>
  </ros2_control>

  <ros2_control name="rear_left_shoulder_control" type="system">
    <hardware>
      <plugin>gazebo_ros2_control/GazeboSystem</plugin>
    </hardware>
    <joint name="rear_left_shoulder">
      <command_interface name="effort"/>
      <state_interface name="position"/>
      <state_interface name="velocity"/>
    </joint>
  </ros2_control>
  <ros2_control name="rear_left_leg_control" type="system">
    <hardware>
      <plugin>gazebo_ros2_control/GazeboSystem</plugin>
    </hardware>
    <joint name="rear_left_leg">
      <command_interface name="effort"/>
      <state_interface name="position"/>
      <state_interface name="velocity"/>
    </joint>
  </ros2_control>
  <ros2_control name="rear_left_foot_control" type="system">
    <hardware>
      <plugin>gazebo_ros2_control/GazeboSystem</plugin>
    </hardware>
    <joint name="rear_left_foot">
      <command_interface name="effort"/>
      <state_interface name="position"/>
      <state_interface name="velocity"/>
    </joint>
  </ros2_control>

  <ros2_control name="rear_right_shoulder_control" type="system">
    <hardware>
      <plugin>gazebo_ros2_control/GazeboSystem</plugin>
    </hardware>
    <joint name="rear_right_shoulder">
      <command_interface name="effort"/>
      <state_interface name="position"/>
      <state_interface name="velocity"/>
    </joint>
  </ros2_control>
  <ros2_control name="rear_right_leg_control" type="system">
    <hardware>
      <plugin>gazebo_ros2_control/GazeboSystem</plugin>
    </hardware>
    <joint name="rear_right_leg">
      <command_interface name="effort"/>
      <state_interface name="position"/>
      <state_interface name="velocity"/>
    </joint>
  </ros2_control>
  <ros2_control name="rear_right_foot_control" type="system">
    <hardware>
      <plugin>gazebo_ros2_control/GazeboSystem</plugin>
    </hardware>
    <joint name="rear_right_foot">
      <command_interface name="effort"/>
      <state_interface name="position"/>
      <state_interface name="velocity"/>
    </joint>
  </ros2_control>


  <gazebo>
    <plugin filename="libgazebo_ros_p3d.so" name="p3d_base_controller">
      <ros>
        <namespace></namespace>
        <argument>odom:=odom/ground_truth</argument>
      </ros>
      <body_name>base_link</body_name>
      <frame_name>world</frame_name>
      <update_rate>10.0</update_rate>
      <xyz_offset>0 0 0</xyz_offset>
      <rpy_offset>0 0 0</rpy_offset>
      <gaussian_noise>0.01</gaussian_noise>
    </plugin>
  </gazebo>
  <gazebo>
    <plugin filename="libgazebo_ros2_control.so" name="gazebo_ros2_control">
      <parameters>$(find quadruped_robot)/config/spot_control.yaml</parameters>
    </plugin>
  </gazebo>
  


</robot>